Workbook

Sheet Params
A1: EMBA-AI-SIM Round 1 · 外生参数 & WTP & SAM（含Excel公式）
A3: 【A】全局参数（黄色 = 可修改）
A4: 参数名 | B4: 数值 | C4: 说明
A5: LOVOT真实售价锚点（元） | B5: 30000 | C5: 用于反推各格子WTP中位数的价格锚点
A6: ToB阶梯数 N_STEPS | B6: 20 | C6: 把分布切成N等份；B端每bucket按上限支付，B端mean = Σ(bucket上限价格)/N
A8: 【B】分布形状参数——DIFF格用正态(cv)，COST格用对数正态(σ_log)
A9: 参数 | B9: ELDER | C9: ADULT | D9: CHILD | E9: 说明
A10: cv（正态，DIFF格） | B10: 0.35 | C10: 0.4 | D10: 0.38 | E10: 变异系数 σ/μ；越大分布越宽
A11: σ_log（对数正态，COST格） | B11: 0.5 | C11: 0.55 | D11: 0.5 | E11: 对数正态形状参数；越大右偏越重
A13: 【C】Percentile——LOVOT ¥60,000 在各ToC格子WTP分布中的分位数（黄色可改）
A14: 格子 | B14: Percentile | C14: 分布类型 | D14: 说明
A15: ToC_DIFF_ELDER | B15: 0.97 | C15: 正态 | D15: 97%分位→仅3%老年人负担得起LOVOT
A16: ToC_DIFF_ADULT | B16: 0.97 | C16: 正态 | D16: 成年差异化市场
A17: ToC_DIFF_CHILD | B17: 0.97 | C17: 正态 | D17: 儿童差异化（校准后统一97%）
A18: ToC_COST_ELDER | B18: 0.97 | C18: 对数正态 | D18: 大众老年，93%分位
A19: ToC_COST_ADULT | B19: 0.97 | C19: 对数正态 | D19: 大众成年，95%分位
A20: ToC_COST_CHILD | B20: 0.97 | C20: 对数正态 | D20: 大众儿童（校准后统一97%）
A22: 【D】N（覆盖人口，万人）& Awareness（品类认知度）
A23: 细分 | B23: N_DIFF（万人） | C23: N_COST（万人） | D23: Awareness | E23: friction | F23: f（渠道费率） | G23: 说明
A24: ToC_ELDER | B24: 1200 | C24: 2400 | D24: 0.16 | E24: 1 | F24: 0.25 | G24: 城镇有消费力老年人口
A25: ToC_ADULT | B25: 1800 | C25: 3600 | D25: 0.115 | E25: 1 | F25: 0.25 | G25: 城镇中产成年人口
A26: ToC_CHILD | B26: 1300 | C26: 2600 | D26: 0.17 | E26: 1 | F26: 0.25 | G26: 城镇有娃家庭
A27: ToB_ELDER | B27: 800 | C27: 1600 | D27: 0.22 | E27: 0.8667 | F27: 0.15 | G27: 养老机构覆盖人口
A28: ToB_ADULT | B28: 1500 | C28: 3000 | D28: 0.12 | E28: 0.65 | F28: 0.15 | G28: 企业/酒店/服务场景覆盖人口
A29: ToB_CHILD | B29: 1000 | C29: 2000 | D29: 0.19 | E29: 1 | F29: 0.15 | G29: 学校/教培覆盖儿童
A31: 【E】计算结果——绿色底色为Excel公式，修改上方参数后自动更新
A32: 格子 | B32: 分布类型 | C32: Percentile | D32: cv / σ_log | E32: WTP mean（元） （DIFF=μ，COST=exp(μ_log+σ²/2)） | F32: ToB WTP mean（元） | G32: B端mean 计算方式 | H32: N（万人） | I32: Awareness | J32: SAM（亿元） | K32: 备注
A33: ToC_DIFF_ELDER | B33: 正态 | C33: =B15 | D33: =B10 | E33: =$B5/(1+B10*NORMINV(B15,0,1)) | F33: — | G33: — | H33: =B24 | I33: =D24 | J33: =H33*I33*E33/10000 | K33: DIFF: N小×WTP高
A34: ToC_DIFF_ADULT | B34: 正态 | C34: =B16 | D34: =C10 | E34: =$B5/(1+C10*NORMINV(B16,0,1)) | F34: — | G34: — | H34: =B25 | I34: =D25 | J34: =H34*I34*E34/10000 | K34: DIFF: N小×WTP高
A35: ToC_DIFF_CHILD | B35: 正态 | C35: =B17 | D35: =D10 | E35: =$B5/(1+D10*NORMINV(B17,0,1)) | F35: — | G35: — | H35: =B26 | I35: =D26 | J35: =H35*I35*E35/10000 | K35: DIFF: N小×WTP高
A36: ToC_COST_ELDER | B36: 对数正态 | C36: =B18 | D36: =B11 | E36: =EXP(LN($B$5)-B11*NORMINV(B18,0,1)+B11^2/2) | F36: — | G36: — | H36: =C24 | I36: =D24 | J36: =H36*I36*E36/10000 | K36: COST: N大×WTP低
A37: ToC_COST_ADULT | B37: 对数正态 | C37: =B19 | D37: =C11 | E37: =EXP(LN($B$5)-C11*NORMINV(B19,0,1)+C11^2/2) | F37: — | G37: — | H37: =C25 | I37: =D25 | J37: =H37*I37*E37/10000 | K37: COST: N大×WTP低
A38: ToC_COST_CHILD | B38: 对数正态 | C38: =B20 | D38: =D11 | E38: =EXP(LN($B$5)-D11*NORMINV(B20,0,1)+D11^2/2) | F38: — | G38: — | H38: =C26 | I38: =D26 | J38: =H38*I38*E38/10000 | K38: COST: N大×WTP低
A40: ToB_DIFF_ELDER | B40: 正态(阶梯) | C40: =B15 | D40: =B10 | E40: =$B5/(1+B10*NORMINV(B15,0,1)) | F40: =AVERAGEIF(Aux!D3:D102,"<>") | G40: =B6&"buckets上限均值" | H40: =B27 | I40: =D27 | J40: =H40*I40*F40/10000 | K40: B端=每bucket上限均值
A41: ToB_DIFF_ADULT | B41: 正态(阶梯) | C41: =B16 | D41: =C10 | E41: =$B5/(1+C10*NORMINV(B16,0,1)) | F41: =AVERAGEIF(Aux!E3:E102,"<>") | G41: =B6&"buckets上限均值" | H41: =B28 | I41: =D28 | J41: =H41*I41*F41/10000 | K41: B端=每bucket上限均值
A42: ToB_DIFF_CHILD | B42: 正态(阶梯) | C42: =B17 | D42: =D10 | E42: =$B5/(1+D10*NORMINV(B17,0,1)) | F42: =AVERAGEIF(Aux!F3:F102,"<>") | G42: =B6&"buckets上限均值" | H42: =B29 | I42: =D29 | J42: =H42*I42*F42/10000 | K42: B端=每bucket上限均值
A43: ToB_COST_ELDER | B43: 对数正态(阶梯) | C43: =B18 | D43: =B11 | E43: =EXP(LN($B$5)-B11*NORMINV(B18,0,1)+B11^2/2) | F43: =AVERAGEIF(Aux!G3:G102,"<>") | G43: =B6&"buckets上限均值" | H43: =C27 | I43: =D27 | J43: =H43*I43*F43/10000 | K43: B端=每bucket上限均值
A44: ToB_COST_ADULT | B44: 对数正态(阶梯) | C44: =B19 | D44: =C11 | E44: =EXP(LN($B$5)-C11*NORMINV(B19,0,1)+C11^2/2) | F44: =AVERAGEIF(Aux!H3:H102,"<>") | G44: =B6&"buckets上限均值" | H44: =C28 | I44: =D28 | J44: =H44*I44*F44/10000 | K44: B端=每bucket上限均值
A45: ToB_COST_CHILD | B45: 对数正态(阶梯) | C45: =B20 | D45: =D11 | E45: =EXP(LN($B$5)-D11*NORMINV(B20,0,1)+D11^2/2) | F45: =AVERAGEIF(Aux!I3:I102,"<>") | G45: =B6&"buckets上限均值" | H45: =C29 | I45: =D29 | J45: =H45*I45*F45/10000 | K45: B端=每bucket上限均值
A47: 【F】Round 2 成本参数
...

Sheet Aux
A1: 辅助计算：B端bucket上限价格（动态，随Params!B6的N_STEPS自动更新）
A2: bucket i | B2: hi_p | C2: z=NORMINV(hi_p) | D2: ToB_DIFF_ELDER | E2: ToB_DIFF_ADULT | F2: ToB_DIFF_CHILD | G2: ToB_COST_ELDER | H2: ToB_COST_ADULT | I2: ToB_COST_CHILD
A3: 1 | B3: =IF(A3<=Params!$B$6, MIN(A3/Params!$B$6, 0.9999), "") | C3: =IF(B3="", "", NORMINV(B3,0,1)) | D3: =IF(C3="","",(Params!$B$5/(1+Params!$B$10*NORMINV(Params!$B$15,0,1)))*(1+Params!$B$10*C3)) | E3: =IF(C3="","",(Params!$B$5/(1+Params!$C$10*NORMINV(Params!$B$16,0,1)))*(1+Params!$C$10*C3)) | F3: =IF(C3="","",(Params!$B$5/(1+Params!$D$10*NORMINV(Params!$B$17,0,1)))*(1+Params!$D$10*C3)) | G3: =IF(C3="","",EXP(LN(Params!$B$5)-Params!$B$11*NORMINV(Params!$B$18,0,1)+Params!$B$11*C3)) | H3: =IF(C3="","",EXP(LN(Params!$B$5)-Params!$C$11*NORMINV(Params!$B$19,0,1)+Params!$C$11*C3)) | I3: =IF(C3="","",EXP(LN(Params!$B$5)-Params!$D$11*NORMINV(Params!$B$20,0,1)+Params!$D$11*C3))
A4: 2 | B4: =IF(A4<=Params!$B$6, MIN(A4/Params!$B$6, 0.9999), "") | C4: =IF(B4="", "", NORMINV(B4,0,1)) | D4: =IF(C4="","",(Params!$B$5/(1+Params!$B$10*NORMINV(Params!$B$15,0,1)))*(1+Params!$B$10*C4)) | E4: =IF(C4="","",(Params!$B$5/(1+Params!$C$10*NORMINV(Params!$B$16,0,1)))*(1+Params!$C$10*C4)) | F4: =IF(C4="","",(Params!$B$5/(1+Params!$D$10*NORMINV(Params!$B$17,0,1)))*(1+Params!$D$10*C4)) | G4: =IF(C4="","",EXP(LN(Params!$B$5)-Params!$B$11*NORMINV(Params!$B$18,0,1)+Params!$B$11*C4)) | H4: =IF(C4="","",EXP(LN(Params!$B$5)-Params!$C$11*NORMINV(Params!$B$19,0,1)+Params!$C$11*C4)) | I4: =IF(C4="","",EXP(LN(Params!$B$5)-Params!$D$11*NORMINV(Params!$B$20,0,1)+Params!$D$11*C4))
A5: 3 | B5: =IF(A5<=Params!$B$6, MIN(A5/Params!$B$6, 0.9999), "") | C5: =IF(B5="", "", NORMINV(B5,0,1)) | D5: =IF(C5="","",(Params!$B$5/(1+Params!$B$10*NORMINV(Params!$B$15,0,1)))*(1+Params!$B$10*C5)) | E5: =IF(C5="","",(Params!$B$5/(1+Params!$C$10*NORMINV(Params!$B$16,0,1)))*(1+Params!$C$10*C5)) | F5: =IF(C5="","",(Params!$B$5/(1+Params!$D$10*NORMINV(Params!$B$17,0,1)))*(1+Params!$D$10*C5)) | G5: =IF(C5="","",EXP(LN(Params!$B$5)-Params!$B$11*NORMINV(Params!$B$18,0,1)+Params!$B$11*C5)) | H5: =IF(C5="","",EXP(LN(Params!$B$5)-Params!$C$11*NORMINV(Params!$B$19,0,1)+Params!$C$11*C5)) | I5: =IF(C5="","",EXP(LN(Params!$B$5)-Params!$D$11*NORMINV(Params!$B$20,0,1)+Params!$D$11*C5))
A6: 4 | B6: =IF(A6<=Params!$B$6, MIN(A6/Params!$B$6, 0.9999), "") | C6: =IF(B6="", "", NORMINV(B6,0,1)) | D6: =IF(C6="","",(Params!$B$5/(1+Params!$B$10*NORMINV(Params!$B$15,0,1)))*(1+Params!$B$10*C6)) | E6: =IF(C6="","",(Params!$B$5/(1+Params!$C$10*NORMINV(Params!$B$16,0,1)))*(1+Params!$C$10*C6)) | F6: =IF(C6="","",(Params!$B$5/(1+Params!$D$10*NORMINV(Params!$B$17,0,1)))*(1+Params!$D$10*C6)) | G6: =IF(C6="","",EXP(LN(Params!$B$5)-Params!$B$11*NORMINV(Params!$B$18,0,1)+Params!$B$11*C6)) | H6: =IF(C6="","",EXP(LN(Params!$B$5)-Params!$C$11*NORMINV(Params!$B$19,0,1)+Params!$C$11*C6)) | I6: =IF(C6="","",EXP(LN(Params!$B$5)-Params!$D$11*NORMINV(Params!$B$20,0,1)+Params!$D$11*C6))
A7: 5 | B7: =IF(A7<=Params!$B$6, MIN(A7/Params!$B$6, 0.9999), "") | C7: =IF(B7="", "", NORMINV(B7,0,1)) | D7: =IF(C7="","",(Params!$B$5/(1+Params!$B$10*NORMINV(Params!$B$15,0,1)))*(1+Params!$B$10*C7)) | E7: =IF(C7="","",(Params!$B$5/(1+Params!$C$10*NORMINV(Params!$B$16,0,1)))*(1+Params!$C$10*C7)) | F7: =IF(C7="","",(Params!$B$5/(1+Params!$D$10*NORMINV(Params!$B$17,0,1)))*(1+Params!$D$10*C7)) | G7: =IF(C7="","",EXP(LN(Params!$B$5)-Params!$B$11*NORMINV(Params!$B$18,0,1)+Params!$B$11*C7)) | H7: =IF(C7="","",EXP(LN(Params!$B$5)-Params!$C$11*NORMINV(Params!$B$19,0,1)+Params!$C$11*C7)) | I7: =IF(C7="","",EXP(LN(Params!$B$5)-Params!$D$11*NORMINV(Params!$B$20,0,1)+Params!$D$11*C7))
A8: 6 | B8: =IF(A8<=Params!$B$6, MIN(A8/Params!$B$6, 0.9999), "") | C8: =IF(B8="", "", NORMINV(B8,0,1)) | D8: =IF(C8="","",(Params!$B$5/(1+Params!$B$10*NORMINV(Params!$B$15,0,1)))*(1+Params!$B$10*C8)) | E8: =IF(C8="","",(Params!$B$5/(1+Params!$C$10*NORMINV(Params!$B$16,0,1)))*(1+Params!$C$10*C8)) | F8: =IF(C8="","",(Params!$B$5/(1+Params!$D$10*NORMINV(Params!$B$17,0,1)))*(1+Params!$D$10*C8)) | G8: =IF(C8="","",EXP(LN(Params!$B$5)-Params!$B$11*NORMINV(Params!$B$18,0,1)+Params!$B$11*C8)) | H8: =IF(C8="","",EXP(LN(Params!$B$5)-Params!$C$11*NORMINV(Params!$B$19,0,1)+Params!$C$11*C8)) | I8: =IF(C8="","",EXP(LN(Params!$B$5)-Params!$D$11*NORMINV(Params!$B$20,0,1)+Params!$D$11*C8))
A9: 7 | B9: =IF(A9<=Params!$B$6, MIN(A9/Params!$B$6, 0.9999), "") | C9: =IF(B9="", "", NORMINV(B9,0,1)) | D9: =IF(C9="","",(Params!$B$5/(1+Params!$B$10*NORMINV(Params!$B$15,0,1)))*(1+Params!$B$10*C9)) | E9: =IF(C9="","",(Params!$B$5/(1+Params!$C$10*NORMINV(Params!$B$16,0,1)))*(1+Params!$C$10*C9)) | F9: =IF(C9="","",(Params!$B$5/(1+Params!$D$10*NORMINV(Params!$B$17,0,1)))*(1+Params!$D$10*C9)) | G9: =IF(C9="","",EXP(LN(Params!$B$5)-Params!$B$11*NORMINV(Params!$B$18,0,1)+Params!$B$11*C9)) | H9: =IF(C9="","",EXP(LN(Params!$B$5)-Params!$C$11*NORMINV(Params!$B$19,0,1)+Params!$C$11*C9)) | I9: =IF(C9="","",EXP(LN(Params!$B$5)-Params!$D$11*NORMINV(Params!$B$20,0,1)+Params!$D$11*C9))
A10: 8 | B10: =IF(A10<=Params!$B$6, MIN(A10/Params!$B$6, 0.9999), "") | C10: =IF(B10="", "", NORMINV(B10,0,1)) | D10: =IF(C10="","",(Params!$B$5/(1+Params!$B$10*NORMINV(Params!$B$15,0,1)))*(1+Params!$B$10*C10)) | E10: =IF(C10="","",(Params!$B$5/(1+Params!$C$10*NORMINV(Params!$B$16,0,1)))*(1+Params!$C$10*C10)) | F10: =IF(C10="","",(Params!$B$5/(1+Params!$D$10*NORMINV(Params!$B$17,0,1)))*(1+Params!$D$10*C10)) | G10: =IF(C10="","",EXP(LN(Params!$B$5)-Params!$B$11*NORMINV(Params!$B$18,0,1)+Params!$B$11*C10)) | H10: =IF(C10="","",EXP(LN(Params!$B$5)-Params!$C$11*NORMINV(Params!$B$19,0,1)+Params!$C$11*C10)) | I10: =IF(C10="","",EXP(LN(Params!$B$5)-Params!$D$11*NORMINV(Params!$B$20,0,1)+Params!$D$11*C10))
A11: 9 | B11: =IF(A11<=Params!$B$6, MIN(A11/Params!$B$6, 0.9999), "") | C11: =IF(B11="", "", NORMINV(B11,0,1)) | D11: =IF(C11="","",(Params!$B$5/(1+Params!$B$10*NORMINV(Params!$B$15,0,1)))*(1+Params!$B$10*C11)) | E11: =IF(C11="","",(Params!$B$5/(1+Params!$C$10*NORMINV(Params!$B$16,0,1)))*(1+Params!$C$10*C11)) | F11: =IF(C11="","",(Params!$B$5/(1+Params!$D$10*NORMINV(Params!$B$17,0,1)))*(1+Params!$D$10*C11)) | G11: =IF(C11="","",EXP(LN(Params!$B$5)-Params!$B$11*NORMINV(Params!$B$18,0,1)+Params!$B$11*C11)) | H11: =IF(C11="","",EXP(LN(Params!$B$5)-Params!$C$11*NORMINV(Params!$B$19,0,1)+Params!$C$11*C11)) | I11: =IF(C11="","",EXP(LN(Params!$B$5)-Params!$D$11*NORMINV(Params!$B$20,0,1)+Params!$D$11*C11))
A12: 10 | B12: =IF(A12<=Params!$B$6, MIN(A12/Params!$B$6, 0.9999), "") | C12: =IF(B12="", "", NORMINV(B12,0,1)) | D12: =IF(C12="","",(Params!$B$5/(1+Params!$B$10*NORMINV(Params!$B$15,0,1)))*(1+Params!$B$10*C12)) | E12: =IF(C12="","",(Params!$B$5/(1+Params!$C$10*NORMINV(Params!$B$16,0,1)))*(1+Params!$C$10*C12)) | F12: =IF(C12="","",(Params!$B$5/(1+Params!$D$10*NORMINV(Params!$B$17,0,1)))*(1+Params!$D$10*C12)) | G12: =IF(C12="","",EXP(LN(Params!$B$5)-Params!$B$11*NORMINV(Params!$B$18,0,1)+Params!$B$11*C12)) | H12: =IF(C12="","",EXP(LN(Params!$B$5)-Params!$C$11*NORMINV(Params!$B$19,0,1)+Params!$C$11*C12)) | I12: =IF(C12="","",EXP(LN(Params!$B$5)-Params!$D$11*NORMINV(Params!$B$20,0,1)+Params!$D$11*C12))
A13: 11 | B13: =IF(A13<=Params!$B$6, MIN(A13/Params!$B$6, 0.9999), "") | C13: =IF(B13="", "", NORMINV(B13,0,1)) | D13: =IF(C13="","",(Params!$B$5/(1+Params!$B$10*NORMINV(Params!$B$15,0,1)))*(1+Params!$B$10*C13)) | E13: =IF(C13="","",(Params!$B$5/(1+Params!$C$10*NORMINV(Params!$B$16,0,1)))*(1+Params!$C$10*C13)) | F13: =IF(C13="","",(Params!$B$5/(1+Params!$D$10*NORMINV(Params!$B$17,0,1)))*(1+Params!$D$10*C13)) | G13: =IF(C13="","",EXP(LN(Params!$B$5)-Params!$B$11*NORMINV(Params!$B$18,0,1)+Params!$B$11*C13)) | H13: =IF(C13="","",EXP(LN(Params!$B$5)-Params!$C$11*NORMINV(Params!$B$19,0,1)+Params!$C$11*C13)) | I13: =IF(C13="","",EXP(LN(Params!$B$5)-Params!$D$11*NORMINV(Params!$B$20,0,1)+Params!$D$11*C13))
A14: 12 | B14: =IF(A14<=Params!$B$6, MIN(A14/Params!$B$6, 0.9999), "") | C14: =IF(B14="", "", NORMINV(B14,0,1)) | D14: =IF(C14="","",(Params!$B$5/(1+Params!$B$10*NORMINV(Params!$B$15,0,1)))*(1+Params!$B$10*C14)) | E14: =IF(C14="","",(Params!$B$5/(1+Params!$C$10*NORMINV(Params!$B$16,0,1)))*(1+Params!$C$10*C14)) | F14: =IF(C14="","",(Params!$B$5/(1+Params!$D$10*NORMINV(Params!$B$17,0,1)))*(1+Params!$D$10*C14)) | G14: =IF(C14="","",EXP(LN(Params!$B$5)-Params!$B$11*NORMINV(Params!$B$18,0,1)+Params!$B$11*C14)) | H14: =IF(C14="","",EXP(LN(Params!$B$5)-Params!$C$11*NORMINV(Params!$B$19,0,1)+Params!$C$11*C14)) | I14: =IF(C14="","",EXP(LN(Params!$B$5)-Params!$D$11*NORMINV(Params!$B$20,0,1)+Params!$D$11*C14))
... A102: 100 | B102: =IF(A102<=Params!$B$6, MIN(A102/Params!$B$6, 0.9999), "") | C102: =IF(B102="", "", NORMINV(B102,0,1)) | D102: =IF(C102="","",(Params!$B$5/(1+Params!$B$10*NORMINV(Params!$B$15,0,1)))*(1+Params!$B$10*C102)) | E102: =IF(C102="","",(Params!$B$5/(1+Params!$C$10*NORMINV(Params!$B$16,0,1)))*(1+Params!$C$10*C102)) | F102: =IF(C102="","",(Params!$B$5/(1+Params!$D$10*NORMINV(Params!$B$17,0,1)))*(1+Params!$D$10*C102)) | G102: =IF(C102="","",EXP(LN(Params!$B$5)-Params!$B$11*NORMINV(Params!$B$18,0,1)+Params!$B$11*C102)) | H102: =IF(C102="","",EXP(LN(Params!$B$5)-Params!$C$11*NORMINV(Params!$B$19,0,1)+Params!$C$11*C102)) | I102: =IF(C102="","",EXP(LN(Params!$B$5)-Params!$D$11*NORMINV(Params!$B$20,0,1)+Params!$D$11*C102))
